[2023-12-19 03:39:17] [INFO    ] discord.client: logging in using static token
[2023-12-19 03:39:19] [INFO    ] discord.gateway: Shard ID None has connected to Gateway (Session ID: 940e52a99286380986b508d0568a829b).
[2023-12-19 03:40:53] [ERROR   ] discord.ui.view: Ignoring exception in view <View timeout=180.0 children=3> for item <Button style=<ButtonStyle.primary: 1> url=None disabled=False label='Read Here' emoji=None row=None>
Traceback (most recent call last):
  File "C:\Users\lyfes\AppData\Local\Packages\PythonSoftwareFoundation.Python.3.11_qbz5n2kfra8p0\LocalCache\local-packages\Python311\site-packages\discord\ui\view.py", line 427, in _scheduled_task
    await item.callback(interaction)
  File "c:\Users\lyfes\Documents\Coding\MangaArc\cogs\manga.py", line 143, in read_here
    view.chapter_title = self.result.latest_chapter_title
                         ^^^^^^^^^^^
AttributeError: 'Manga' object has no attribute 'result'
[2023-12-19 03:41:27] [ERROR   ] discord.ui.view: Ignoring exception in view <View timeout=180.0 children=3> for item <Button style=<ButtonStyle.primary: 1> url=None disabled=False label='Read Here' emoji=None row=None>
Traceback (most recent call last):
  File "C:\Users\lyfes\AppData\Local\Packages\PythonSoftwareFoundation.Python.3.11_qbz5n2kfra8p0\LocalCache\local-packages\Python311\site-packages\discord\ui\view.py", line 427, in _scheduled_task
    await item.callback(interaction)
  File "c:\Users\lyfes\Documents\Coding\MangaArc\cogs\manga.py", line 143, in read_here
    view.chapter_title = self.result.latest_chapter_title
                         ^^^^^^^^^^^
AttributeError: 'Manga' object has no attribute 'result'
[2023-12-19 03:42:58] [ERROR   ] discord.ui.view: Ignoring exception in view <View timeout=180.0 children=3> for item <Button style=<ButtonStyle.primary: 1> url=None disabled=False label='Read Here' emoji=None row=None>
Traceback (most recent call last):
  File "C:\Users\lyfes\AppData\Local\Packages\PythonSoftwareFoundation.Python.3.11_qbz5n2kfra8p0\LocalCache\local-packages\Python311\site-packages\discord\ui\view.py", line 427, in _scheduled_task
    await item.callback(interaction)
  File "c:\Users\lyfes\Documents\Coding\MangaArc\cogs\manga.py", line 143, in read_here
    view.chapter_title = self.manga.latest_chapter_title
                         ^^^^^^^^^^^
AttributeError: 'Manga' object has no attribute 'result'
[2023-12-19 03:45:13] [ERROR   ] discord.ext.commands.bot: Ignoring exception in command rcog
Traceback (most recent call last):
  File "C:\Users\lyfes\AppData\Local\Packages\PythonSoftwareFoundation.Python.3.11_qbz5n2kfra8p0\LocalCache\local-packages\Python311\site-packages\discord\ext\commands\core.py", line 235, in wrapped
    ret = await coro(*args, **kwargs)
          ^^^^^^^^^^^^^^^^^^^^^^^^^^^
  File "c:\Users\lyfes\Documents\Coding\MangaArc\main.py", line 46, in rcog
    await bot.reload_extension(f"cogs.{arg}")
  File "C:\Users\lyfes\AppData\Local\Packages\PythonSoftwareFoundation.Python.3.11_qbz5n2kfra8p0\LocalCache\local-packages\Python311\site-packages\discord\ext\commands\bot.py", line 1102, in reload_extension
    raise errors.ExtensionNotLoaded(name)
discord.ext.commands.errors.ExtensionNotLoaded: Extension 'cogs.man' has not been loaded.

The above exception was the direct cause of the following exception:

Traceback (most recent call last):
  File "C:\Users\lyfes\AppData\Local\Packages\PythonSoftwareFoundation.Python.3.11_qbz5n2kfra8p0\LocalCache\local-packages\Python311\site-packages\discord\ext\commands\bot.py", line 1350, in invoke
    await ctx.command.invoke(ctx)
  File "C:\Users\lyfes\AppData\Local\Packages\PythonSoftwareFoundation.Python.3.11_qbz5n2kfra8p0\LocalCache\local-packages\Python311\site-packages\discord\ext\commands\core.py", line 1029, in invoke
    await injected(*ctx.args, **ctx.kwargs)  # type: ignore
    ^^^^^^^^^^^^^^^^^^^^^^^^^^^^^^^^^^^^^^^
  File "C:\Users\lyfes\AppData\Local\Packages\PythonSoftwareFoundation.Python.3.11_qbz5n2kfra8p0\LocalCache\local-packages\Python311\site-packages\discord\ext\commands\core.py", line 244, in wrapped
    raise CommandInvokeError(exc) from exc
discord.ext.commands.errors.CommandInvokeError: Command raised an exception: ExtensionNotLoaded: Extension 'cogs.man' has not been loaded.
