[2023-12-22 14:20:42] [INFO    ] discord.client: logging in using static token
[2023-12-22 14:20:44] [INFO    ] discord.gateway: Shard ID None has connected to Gateway (Session ID: 497e54eba8854e8f2cb7247891e5eb25).
[2023-12-22 16:01:09] [ERROR   ] discord.ext.commands.bot: Ignoring exception in command None
discord.ext.commands.errors.CommandNotFound: Command "mangaa" is not found
[2023-12-22 16:07:17] [ERROR   ] discord.ext.commands.bot: Ignoring exception in command rcog
Traceback (most recent call last):
  File "C:\Users\lyfes\AppData\Local\Packages\PythonSoftwareFoundation.Python.3.11_qbz5n2kfra8p0\LocalCache\local-packages\Python311\site-packages\discord\ext\commands\core.py", line 235, in wrapped
    ret = await coro(*args, **kwargs)
          ^^^^^^^^^^^^^^^^^^^^^^^^^^^
  File "c:\Users\lyfes\Documents\Coding\MangaArc\main.py", line 52, in rcog
    await bot.reload_extension(f"cogs.{arg}")
  File "C:\Users\lyfes\AppData\Local\Packages\PythonSoftwareFoundation.Python.3.11_qbz5n2kfra8p0\LocalCache\local-packages\Python311\site-packages\discord\ext\commands\bot.py", line 1102, in reload_extension
    raise errors.ExtensionNotLoaded(name)
discord.ext.commands.errors.ExtensionNotLoaded: Extension 'cogs.animee' has not been loaded.

The above exception was the direct cause of the following exception:

Traceback (most recent call last):
  File "C:\Users\lyfes\AppData\Local\Packages\PythonSoftwareFoundation.Python.3.11_qbz5n2kfra8p0\LocalCache\local-packages\Python311\site-packages\discord\ext\commands\bot.py", line 1350, in invoke
    await ctx.command.invoke(ctx)
  File "C:\Users\lyfes\AppData\Local\Packages\PythonSoftwareFoundation.Python.3.11_qbz5n2kfra8p0\LocalCache\local-packages\Python311\site-packages\discord\ext\commands\core.py", line 1029, in invoke
    await injected(*ctx.args, **ctx.kwargs)  # type: ignore
    ^^^^^^^^^^^^^^^^^^^^^^^^^^^^^^^^^^^^^^^
  File "C:\Users\lyfes\AppData\Local\Packages\PythonSoftwareFoundation.Python.3.11_qbz5n2kfra8p0\LocalCache\local-packages\Python311\site-packages\discord\ext\commands\core.py", line 244, in wrapped
    raise CommandInvokeError(exc) from exc
discord.ext.commands.errors.CommandInvokeError: Command raised an exception: ExtensionNotLoaded: Extension 'cogs.animee' has not been loaded.
[2023-12-22 16:07:42] [ERROR   ] discord.ext.commands.bot: Ignoring exception in command anime
Traceback (most recent call last):
  File "C:\Users\lyfes\AppData\Local\Packages\PythonSoftwareFoundation.Python.3.11_qbz5n2kfra8p0\LocalCache\local-packages\Python311\site-packages\discord\ext\commands\core.py", line 235, in wrapped
    ret = await coro(*args, **kwargs)
          ^^^^^^^^^^^^^^^^^^^^^^^^^^^
  File "c:\Users\lyfes\Documents\Coding\MangaArc\cogs\anime.py", line 108, in anime
    await api_search.get_by_title(ctx, delim[0], delim[1])
                                                 ~~~~~^^^
IndexError: list index out of range

The above exception was the direct cause of the following exception:

Traceback (most recent call last):
  File "C:\Users\lyfes\AppData\Local\Packages\PythonSoftwareFoundation.Python.3.11_qbz5n2kfra8p0\LocalCache\local-packages\Python311\site-packages\discord\ext\commands\bot.py", line 1350, in invoke
    await ctx.command.invoke(ctx)
  File "C:\Users\lyfes\AppData\Local\Packages\PythonSoftwareFoundation.Python.3.11_qbz5n2kfra8p0\LocalCache\local-packages\Python311\site-packages\discord\ext\commands\core.py", line 1029, in invoke
    await injected(*ctx.args, **ctx.kwargs)  # type: ignore
    ^^^^^^^^^^^^^^^^^^^^^^^^^^^^^^^^^^^^^^^
  File "C:\Users\lyfes\AppData\Local\Packages\PythonSoftwareFoundation.Python.3.11_qbz5n2kfra8p0\LocalCache\local-packages\Python311\site-packages\discord\ext\commands\core.py", line 244, in wrapped
    raise CommandInvokeError(exc) from exc
discord.ext.commands.errors.CommandInvokeError: Command raised an exception: IndexError: list index out of range
[2023-12-22 16:08:25] [ERROR   ] discord.ext.commands.bot: Ignoring exception in command anime
Traceback (most recent call last):
  File "C:\Users\lyfes\AppData\Local\Packages\PythonSoftwareFoundation.Python.3.11_qbz5n2kfra8p0\LocalCache\local-packages\Python311\site-packages\discord\ext\commands\core.py", line 235, in wrapped
    ret = await coro(*args, **kwargs)
          ^^^^^^^^^^^^^^^^^^^^^^^^^^^
  File "c:\Users\lyfes\Documents\Coding\MangaArc\cogs\anime.py", line 108, in anime
    await api_search.get_by_title(ctx, delim[0], delim[1])
                                                 ~~~~~^^^
IndexError: list index out of range

The above exception was the direct cause of the following exception:

Traceback (most recent call last):
  File "C:\Users\lyfes\AppData\Local\Packages\PythonSoftwareFoundation.Python.3.11_qbz5n2kfra8p0\LocalCache\local-packages\Python311\site-packages\discord\ext\commands\bot.py", line 1350, in invoke
    await ctx.command.invoke(ctx)
  File "C:\Users\lyfes\AppData\Local\Packages\PythonSoftwareFoundation.Python.3.11_qbz5n2kfra8p0\LocalCache\local-packages\Python311\site-packages\discord\ext\commands\core.py", line 1029, in invoke
    await injected(*ctx.args, **ctx.kwargs)  # type: ignore
    ^^^^^^^^^^^^^^^^^^^^^^^^^^^^^^^^^^^^^^^
  File "C:\Users\lyfes\AppData\Local\Packages\PythonSoftwareFoundation.Python.3.11_qbz5n2kfra8p0\LocalCache\local-packages\Python311\site-packages\discord\ext\commands\core.py", line 244, in wrapped
    raise CommandInvokeError(exc) from exc
discord.ext.commands.errors.CommandInvokeError: Command raised an exception: IndexError: list index out of range
[2023-12-22 16:09:22] [ERROR   ] discord.ext.commands.bot: Ignoring exception in command anime
Traceback (most recent call last):
  File "C:\Users\lyfes\AppData\Local\Packages\PythonSoftwareFoundation.Python.3.11_qbz5n2kfra8p0\LocalCache\local-packages\Python311\site-packages\discord\ext\commands\core.py", line 235, in wrapped
    ret = await coro(*args, **kwargs)
          ^^^^^^^^^^^^^^^^^^^^^^^^^^^
  File "c:\Users\lyfes\Documents\Coding\MangaArc\cogs\anime.py", line 112, in anime
    await api_search.get_by_title(ctx, delim[0])
  File "c:\Users\lyfes\Documents\Coding\MangaArc\cogs\anime.py", line 58, in get_by_title
    response = self.jikan.search(search_type="anime", query=title, parameters={"limit": limit})
               ^^^^^^^^^^^^^^^^^^^^^^^^^^^^^^^^^^^^^^^^^^^^^^^^^^^^^^^^^^^^^^^^^^^^^^^^^^^^^^^^
  File "C:\Users\lyfes\AppData\Local\Packages\PythonSoftwareFoundation.Python.3.11_qbz5n2kfra8p0\LocalCache\local-packages\Python311\site-packages\jikanpy\jikan.py", line 273, in search
    return self._request(url, **kwargs)
           ^^^^^^^^^^^^^^^^^^^^^^^^^^^^
  File "C:\Users\lyfes\AppData\Local\Packages\PythonSoftwareFoundation.Python.3.11_qbz5n2kfra8p0\LocalCache\local-packages\Python311\site-packages\jikanpy\jikan.py", line 85, in _request
    return self._wrap_response(response, url, **kwargs)
           ^^^^^^^^^^^^^^^^^^^^^^^^^^^^^^^^^^^^^^^^^^^^
  File "C:\Users\lyfes\AppData\Local\Packages\PythonSoftwareFoundation.Python.3.11_qbz5n2kfra8p0\LocalCache\local-packages\Python311\site-packages\jikanpy\jikan.py", line 79, in _wrap_response
    raise APIException(response.status_code, json_response, **kwargs)
jikanpy.exceptions.APIException: HTTP 400 - status=400, type=ValidationException, messages={'q': ['The q parameter cannot contain any of the following characters: \\n, \\r, \\t, \\0, %0A']}, error=Invalid or incomplete request. Make sure your request is correct. https://docs.api.jikan.moe/ for search type=anime, query=Ron Kamonohashi: Deranged Detective
Manga series

The above exception was the direct cause of the following exception:

Traceback (most recent call last):
  File "C:\Users\lyfes\AppData\Local\Packages\PythonSoftwareFoundation.Python.3.11_qbz5n2kfra8p0\LocalCache\local-packages\Python311\site-packages\discord\ext\commands\bot.py", line 1350, in invoke
    await ctx.command.invoke(ctx)
  File "C:\Users\lyfes\AppData\Local\Packages\PythonSoftwareFoundation.Python.3.11_qbz5n2kfra8p0\LocalCache\local-packages\Python311\site-packages\discord\ext\commands\core.py", line 1029, in invoke
    await injected(*ctx.args, **ctx.kwargs)  # type: ignore
    ^^^^^^^^^^^^^^^^^^^^^^^^^^^^^^^^^^^^^^^
  File "C:\Users\lyfes\AppData\Local\Packages\PythonSoftwareFoundation.Python.3.11_qbz5n2kfra8p0\LocalCache\local-packages\Python311\site-packages\discord\ext\commands\core.py", line 244, in wrapped
    raise CommandInvokeError(exc) from exc
discord.ext.commands.errors.CommandInvokeError: Command raised an exception: APIException: HTTP 400 - status=400, type=ValidationException, messages={'q': ['The q parameter cannot contain any of the following characters: \\n, \\r, \\t, \\0, %0A']}, error=Invalid or incomplete request. Make sure your request is correct. https://docs.api.jikan.moe/ for search type=anime, query=Ron Kamonohashi: Deranged Detective
Manga series
[2023-12-22 16:13:46] [INFO    ] discord.gateway: Shard ID None has successfully RESUMED session 497e54eba8854e8f2cb7247891e5eb25.
